Workbook

Sheet Maandsamenvatting
A1: 2022 | B1: zakelijk | F1: Prive | I1: BALANS 2022 | J1: 44926 | K1: 44561
A2: Maand | B2: Uren gepland | C2: Inkomsten rijschool | D2: Kilometers | E2: Uurtarief | F2: =IF(Prive!B1="","",Prive!B1) -> ELQ hyp rente | G2: =IF(Prive!C1="","",Prive!C1) -> SVB -PGB Ramasray
A3: januari 2022 | B3: 114 | C3: 3705 | D3: 3079 | E3: 32.5 | F3: =IF(Prive!B2="","",Prive!B2) | G3: =IF(Prive!C2="","",Prive!C2) | I3: ACTIVA
A4: februari 2022 | B4: 123 | C4: 3997.5 | D4: 3333 | E4: 32.5 | F4: =IF(Prive!B3="","",Prive!B3) -> 743.75 | G4: =IF(Prive!C3="","",Prive!C3) | I4: VASTE ACTIVA
A5: maart 2022 | B5: 138 | C5: 4485 | D5: 3770 | E5: 32.5 | F5: =IF(Prive!B4="","",Prive!B4) -> 725.9 | G5: =IF(Prive!C4="","",Prive!C4) | I5: Inventaris (incl computer ed) | J5: =K5 -> 350 | K5: 350
A6: april 2022 | B6: 101 | C6: 3282.5 | D6: 2744 | E6: 32.5 | F6: =IF(Prive!B5="","",Prive!B5) -> 743.75 | G6: =IF(Prive!C5="","",Prive!C5) | I6: afschrijvingen | J6: =K6 -> 150 | K6: 150
A7: mei 2022 | B7: 106 | C7: 3445 | D7: 2869 | E7: 32.5 | F7: =IF(Prive!B6="","",Prive!B6) -> 743.75 | G7: =IF(Prive!C6="","",Prive!C6) | I7: boekwaarde | J7: =J5-J6 -> 200 | K7: 200
A8: juni 2022 | B8: 100 | C8: 3250 | D8: 2683 | E8: 32.5 | F8: =IF(Prive!B7="","",Prive!B7) -> 741.77 | G8: =IF(Prive!C7="","",Prive!C7) | J8: =J7 -> 200 | K8: 200
A9: juli 2022 | B9: 112 | C9: 3640 | D9: 2977 | E9: 32.5 | F9: =IF(Prive!B8="","",Prive!B8) -> 747.72 | G9: =IF(Prive!C8="","",Prive!C8) | I9: VLOTTENDE ACTIVA
A10: augustus 2022 | B10: 140 | C10: 4550 | D10: 3769 | E10: 32.5 | F10: =IF(Prive!B9="","",Prive!B9) -> 805.23 | G10: =IF(Prive!C9="","",Prive!C9) | I10: overige vorderingen | J10: =22*E8 -> 715 | K10: 817
A11: september 2022 | B11: 143 | C11: 4647.5 | D11: 3843 | E11: 32.5 | F11: =IF(Prive!B10="","",Prive!B10) -> 866.72 | G11: =IF(Prive!C10="","",Prive!C10) | J11: =J10 -> 715 | K11: 817
A12: oktober 2022 | B12: 137 | C12: 4452.5 | D12: 3683 | E12: 32.5 | F12: =IF(Prive!B11="","",Prive!B11) -> 989.68 | G12: =IF(Prive!C11="","",Prive!C11) | I12: LIQUIDE MIDDELEN
A13: november 2022 | B13: 131 | C13: 4257.5 | D13: 3505 | E13: 32.5 | F13: =IF(Prive!B12="","",Prive!B12) | G13: =IF(Prive!C12="","",Prive!C12) | I13: Kas/bank | J13: =J27-J8-J11-J14 -> 42440.585 | K13: 15641.875
A14: december 2022 | B14: 110 | C14: 3575 | D14: 2959 | E14: 32.5 | F14: =IF(Prive!B13="","",Prive!B13) -> 1049.18 | G14: =IF(Prive!C13="","",Prive!C13) | I14: priveonttrekkingen | J14: -31200 | K14: -8300
J15: =E335 -> 0 | K15: 7341.8748
A16: Totaal | B16: =SUM(B3:B14) -> 1455 | C16: =SUM(C3:C14) -> 47287.5 | D16: =SUM(D3:D14) -> 39214 | E16: 32.5 | F16: =IF(COUNT(F3:F14)=0,"",SUM(F3:F14)) -> 8157.45 | G16: =IF(COUNT(G3:G14)=0,"",SUM(G3:G14)) | I16: TOTAAL | J16: =SUM(J8,J11,J15) -> 915 | K16: 8358.8748
I18: PASSIVA
A19: Winst- en verliestrekening | I19: Eigen vermogen | J19: =K19+$B25+J14 -> 12155.585 | K19: 9467.4548
A20: Inkomsten - Rijschool | B20: =C16 -> 47287.5
A21: Kosten - Rijschool | B21: =Kosten!D68 -> 4019.485 | I21: Langlopende schulden | J21: =K21 -> 0 | K21: 0
A22: Kosten - km | B22: =D16*0.23 -> 9019.22 | I22: Kortlopende schulden | J22: =K22 -> 0 | K22: 0
A23: Kosten - Internet/Mobiel | B23: 306.4
A24: Totale kosten | B24: 13399.37 | I24: Te Betalen Belastingen | J24: =K24 -> 0 | K24: 0
A25: Resultaat | B25: =B20-B24 -> 33888.13 | I25: cumm | J25: =SUM(J21:J24) -> 0 | K25: 0
C26: =B24+B25 -> 47287.5
I27: TOTAAL | J27: =SUM(J19,J21:J25) -> 12155.585 | K27: 9467.4548
A29: Aantal uren moet nog met 300 worden verminderd

Sheet Rittenplanning
A1: Plandatum | B1: Uren gepland | C1: Km per uur | D1: Kilometers | E1: uren/mnd
A2: 44564 | B2: 4 | C2: 26.25 | D2: 105
A3: 44565 | B3: 3 | C3: 25.67 | D3: 77
A4: 44566 | B4: 5 | C4: 28 | D4: 140
A5: 44567 | B5: 5 | C5: 26.8 | D5: 134
A6: 44568 | B6: 3 | C6: 25.67 | D6: 77
A7: 44569 | B7: 5 | C7: 26.4 | D7: 132
A8: 44571 | B8: 5 | C8: 27.8 | D8: 139
A9: 44572 | B9: 6 | C9: 29.17 | D9: 175
A10: 44573 | B10: 3 | C10: 25 | D10: 75
A11: 44574 | B11: 2 | C11: 26.5 | D11: 53
A12: 44575 | B12: 6 | C12: 27.17 | D12: 163
A13: 44576 | B13: 6 | C13: 25.67 | D13: 154
... A25: 44590 | B25: 4 | C25: 28.25 | D25: 113
A26: 44592 | B26: 5 | C26: 25 | D26: 125 | E26: =SUM(B2:B26) -> 114
A27: 44593 | B27: 6 | C27: 26.83 | D27: 161
A28: 44594 | B28: 6 | C28: 27 | D28: 162
A29: 44595 | B29: 5 | C29: 26.2 | D29: 131
A30: 44596 | B30: 2 | C30: 27 | D30: 54
A31: 44597 | B31: 5 | C31: 28.8 | D31: 144
A32: 44599 | B32: 4 | C32: 28.75 | D32: 115
A33: 44600 | B33: 6 | C33: 25.33 | D33: 152
A34: 44601 | B34: 6 | C34: 27.33 | D34: 164
A35: 44602 | B35: 6 | C35: 26.83 | D35: 161
A36: 44603 | B36: 6 | C36: 27.83 | D36: 167
A37: 44604 | B37: 2 | C37: 27.5 | D37: 55
A38: 44606 | B38: 5 | C38: 28 | D38: 140
... A49: 44618 | B49: 6 | C49: 26.83 | D49: 161
A50: 44620 | B50: 4 | C50: 27 | D50: 108 | E50: =SUM(B27:B50) -> 123
A51: 44621 | B51: 6 | C51: 28.33 | D51: 170
A52: 44622 | B52: 5 | C52: 29.4 | D52: 147
A53: 44623 | B53: 5 | C53: 27.4 | D53: 137
A54: 44624 | B54: 4 | C54: 25 | D54: 100
A55: 44625 | B55: 6 | C55: 26.5 | D55: 159
A56: 44627 | B56: 6 | C56: 27.67 | D56: 166
A57: 44628 | B57: 6 | C57: 27.83 | D57: 167
A58: 44629 | B58: 5 | C58: 27.2 | D58: 136
A59: 44630 | B59: 6 | C59: 27 | D59: 162
A60: 44631 | B60: 3 | C60: 29 | D60: 87
A61: 44632 | B61: 5 | C61: 29 | D61: 145
...

Sheet Transacties
A1: Transactiedatum | B1: Inkomsten rijschool | C1: Uren afgerond | D1: Km per uur | E1: Kilometers | F1: Weken terug
A2: 44567 | B2: 180 | C2: 6 | D2: 26 | E2: 156 | F2: 15
A3: 44571 | B3: 237 | C3: 7 | D3: 27 | E3: 189 | F3: 15
A4: 44578 | B4: 100 | C4: 3 | D4: 28 | E4: 84 | F4: 15
A5: 44579 | B5: 252 | C5: 8 | D5: 29 | E5: 232 | F5: 15
A6: 44585 | B6: 67 | C6: 2 | D6: 30 | E6: 60 | F6: 15
A7: 44587 | B7: 75 | C7: 2 | D7: 31 | E7: 62 | F7: 15
A8: 44589 | B8: 70 | C8: 2 | D8: 23 | E8: 46 | F8: 15
A9: 44592 | B9: 1102 | C9: 34 | D9: 24 | E9: 816 | F9: 20
A10: 44597 | B10: 390 | C10: 12 | D10: 25 | E10: 300 | F10: 15
A11: 44600 | B11: 342 | C11: 11 | D11: 26 | E11: 286 | F11: 15
A12: 44601 | B12: 300 | C12: 9 | D12: 27 | E12: 243 | F12: 15
A13: 44602 | B13: 372 | C13: 11 | D13: 28 | E13: 308 | F13: 15
... A113: 44916 | B113: 245 | C113: 8 | D113: 29 | E113: 232 | F113: 15
A115: Totaal | B115: =SUM(B2:B113) -> 45402.03 | C115: =SUM(C2:C113) -> 1408 | E115: =SUM(E2:E113) -> 37957

Sheet Kosten
A1: Datum | B1: kosten | C1: Omschrijving | D1: decl.knt | E1: decl%
C2: Lesmateriaal | D2: 72 | E2: 1
C3: Kantoor- en administratiekosten | D3: 40 | E3: 1
C4: Kvk | D4: 48 | E4: 1
C5: Reclame en websitekosten | D5: 120 | E5: 1
A6: 44573 | B6: 2.65 | C6: Kosten BasisPakket | D6: =B6*E6 -> 1.325 | E6: 0.5
A7: 44579 | B7: 30.13 | C7: KPN - Mobiel | D7: =B7*E7 -> 30.13 | E7: 1
A8: 44593 | B8: 21.14 | C8: KPN - Mobiel | D8: =B8*E8 -> 21.14 | E8: 1
A9: 44602 | B9: 3.05 | C9: Kosten BasisPakket | D9: =B9*E9 -> 1.525 | E9: 0.5
A10: 44606 | B10: 2.2 | C10: bedrijfsrest 2461 BARENDRECHT | D10: =B10*E10 -> 2.2 | E10: 1
A11: 44623 | B11: 21.14 | C11: KPN - Mobiel | D11: =B11*E11 -> 10.57 | E11: 0.5
A12: 44630 | B12: 3.05 | C12: Kosten BasisPakket | D12: =B12*E12 -> 1.525 | E12: 0.5
A13: 44630 | B13: 393.25 | C13: Rijschool Mado | D13: =B13*E13 -> 393.25 | E13: 1
A14: 44630 | B14: 3.2 | C14: bedrijfsrest 2461 BARENDRECHT | D14: =B14*E14 -> 3.2 | E14: 1
A15: 44636 | B15: 3.2 | C15: bedrijfsrest 2461 BARENDRECHT | D15: =B15*E15 -> 3.2 | E15: 1
A16: 44651 | B16: 2.95 | C16: bedrijfsrest 2461 BARENDRECHT | D16: =B16*E16 -> 2.95 | E16: 1
A17: 44651 | B17: 2.2 | C17: bedrijfsrest 2461 BARENDRECHT | D17: =B17*E17 -> 2.2 | E17: 1
... A67: 44926 | B67: 22.6 | C67: KPN - Mobiel | D67: =B67*E67 -> 11.3 | E67: 0.5
C68: Totaal | D68: =SUM(D2:D67) -> 4019.485

Sheet Prive
A1: 2022 | B1: ELQ hyp rente | C1: SVB -PGB Ramasray
A2: januari
A3: februari | B3: 743.75
A4: maart | B4: 725.9
A5: april | B5: 743.75
A6: mei | B6: 743.75
A7: juni | B7: 741.77
A8: juli | B8: 747.72
A9: augustus | B9: 805.23
A10: september | B10: 866.72
A11: oktober | B11: 989.68
A12: november
A13: december | B13: 1049.18
A14: Totaal | B14: =SUM(B3:B13) -> 8157.45 | C14: =SUM(C3:C13) -> 0
